EFE.
======================================================================
ERROR: test_css (__main__.TestYourWebserver)
----------------------------------------------------------------------
Traceback (most recent call last):
  File "/mnt/d/Program Files (x86)/UNIVERSITY/CMPUT/CMPUT 404/Assignments/Assignment 1/CMPUT404-assignment-webserver/CMPUT404-assignment-webserver/freetests.py", line 30, in test_css
    req = request.urlopen(url, None, 3)
  File "/usr/lib/python3.10/urllib/request.py", line 216, in urlopen
    return opener.open(url, data, timeout)
  File "/usr/lib/python3.10/urllib/request.py", line 525, in open
    response = meth(req, response)
  File "/usr/lib/python3.10/urllib/request.py", line 634, in http_response
    response = self.parent.error(
  File "/usr/lib/python3.10/urllib/request.py", line 563, in error
    return self._call_chain(*args)
  File "/usr/lib/python3.10/urllib/request.py", line 496, in _call_chain
    result = func(*args)
  File "/usr/lib/python3.10/urllib/request.py", line 643, in http_error_default
    raise HTTPError(req.full_url, code, msg, hdrs, fp)
urllib.error.HTTPError: HTTP Error 301: Moved Permenantly

======================================================================
ERROR: test_get_indexhtml (__main__.TestYourWebserver)
----------------------------------------------------------------------
Traceback (most recent call last):
  File "/mnt/d/Program Files (x86)/UNIVERSITY/CMPUT/CMPUT 404/Assignments/Assignment 1/CMPUT404-assignment-webserver/CMPUT404-assignment-webserver/freetests.py", line 41, in test_get_indexhtml
    req = request.urlopen(url, None, 3)
  File "/usr/lib/python3.10/urllib/request.py", line 216, in urlopen
    return opener.open(url, data, timeout)
  File "/usr/lib/python3.10/urllib/request.py", line 525, in open
    response = meth(req, response)
  File "/usr/lib/python3.10/urllib/request.py", line 634, in http_response
    response = self.parent.error(
  File "/usr/lib/python3.10/urllib/request.py", line 563, in error
    return self._call_chain(*args)
  File "/usr/lib/python3.10/urllib/request.py", line 496, in _call_chain
    result = func(*args)
  File "/usr/lib/python3.10/urllib/request.py", line 643, in http_error_default
    raise HTTPError(req.full_url, code, msg, hdrs, fp)
urllib.error.HTTPError: HTTP Error 301: Moved Permenantly

======================================================================
FAIL: test_get_404 (__main__.TestYourWebserver)
----------------------------------------------------------------------
Traceback (most recent call last):
  File "/mnt/d/Program Files (x86)/UNIVERSITY/CMPUT/CMPUT 404/Assignments/Assignment 1/CMPUT404-assignment-webserver/CMPUT404-assignment-webserver/freetests.py", line 48, in test_get_404
    req = request.urlopen(url, None, 3)
  File "/usr/lib/python3.10/urllib/request.py", line 216, in urlopen
    return opener.open(url, data, timeout)
  File "/usr/lib/python3.10/urllib/request.py", line 525, in open
    response = meth(req, response)
  File "/usr/lib/python3.10/urllib/request.py", line 634, in http_response
    response = self.parent.error(
  File "/usr/lib/python3.10/urllib/request.py", line 563, in error
    return self._call_chain(*args)
  File "/usr/lib/python3.10/urllib/request.py", line 496, in _call_chain
    result = func(*args)
  File "/usr/lib/python3.10/urllib/request.py", line 643, in http_error_default
    raise HTTPError(req.full_url, code, msg, hdrs, fp)
urllib.error.HTTPError: HTTP Error 301: Moved Permenantly

During handling of the above exception, another exception occurred:

Traceback (most recent call last):
  File "/mnt/d/Program Files (x86)/UNIVERSITY/CMPUT/CMPUT 404/Assignments/Assignment 1/CMPUT404-assignment-webserver/CMPUT404-assignment-webserver/freetests.py", line 51, in test_get_404
    self.assertTrue( e.getcode()  == 404 , ("404 Not FOUND! %d" % e.getcode()))
AssertionError: False is not true : 404 Not FOUND! 301

----------------------------------------------------------------------
Ran 4 tests in 0.012s

FAILED (failures=1, errors=2)
.E.F.FE.EFE
======================================================================
ERROR: test_css (__main__.TestYourWebserver)
----------------------------------------------------------------------
Traceback (most recent call last):
  File "/mnt/d/Program Files (x86)/UNIVERSITY/CMPUT/CMPUT 404/Assignments/Assignment 1/CMPUT404-assignment-webserver/CMPUT404-assignment-webserver/not-free-tests.py", line 68, in test_css
    req = request.urlopen(url, None, 3)
  File "/usr/lib/python3.10/urllib/request.py", line 216, in urlopen
    return opener.open(url, data, timeout)
  File "/usr/lib/python3.10/urllib/request.py", line 525, in open
    response = meth(req, response)
  File "/usr/lib/python3.10/urllib/request.py", line 634, in http_response
    response = self.parent.error(
  File "/usr/lib/python3.10/urllib/request.py", line 563, in error
    return self._call_chain(*args)
  File "/usr/lib/python3.10/urllib/request.py", line 496, in _call_chain
    result = func(*args)
  File "/usr/lib/python3.10/urllib/request.py", line 643, in http_error_default
    raise HTTPError(req.full_url, code, msg, hdrs, fp)
urllib.error.HTTPError: HTTP Error 301: Moved Permenantly

======================================================================
ERROR: test_get_index (__main__.TestYourWebserver)
----------------------------------------------------------------------
Traceback (most recent call last):
  File "/mnt/d/Program Files (x86)/UNIVERSITY/CMPUT/CMPUT 404/Assignments/Assignment 1/CMPUT404-assignment-webserver/CMPUT404-assignment-webserver/not-free-tests.py", line 42, in test_get_index
    req = request.urlopen(url, None, 3)
  File "/usr/lib/python3.10/urllib/request.py", line 216, in urlopen
    return opener.open(url, data, timeout)
  File "/usr/lib/python3.10/urllib/request.py", line 525, in open
    response = meth(req, response)
  File "/usr/lib/python3.10/urllib/request.py", line 634, in http_response
    response = self.parent.error(
  File "/usr/lib/python3.10/urllib/request.py", line 563, in error
    return self._call_chain(*args)
  File "/usr/lib/python3.10/urllib/request.py", line 496, in _call_chain
    result = func(*args)
  File "/usr/lib/python3.10/urllib/request.py", line 643, in http_error_default
    raise HTTPError(req.full_url, code, msg, hdrs, fp)
urllib.error.HTTPError: HTTP Error 301: Moved Permenantly

======================================================================
ERROR: test_hardcode (__main__.TestYourWebserver)
----------------------------------------------------------------------
Traceback (most recent call last):
  File "/mnt/d/Program Files (x86)/UNIVERSITY/CMPUT/CMPUT 404/Assignments/Assignment 1/CMPUT404-assignment-webserver/CMPUT404-assignment-webserver/not-free-tests.py", line 106, in test_hardcode
    req = request.urlopen(url, None, 3)
  File "/usr/lib/python3.10/urllib/request.py", line 216, in urlopen
    return opener.open(url, data, timeout)
  File "/usr/lib/python3.10/urllib/request.py", line 525, in open
    response = meth(req, response)
  File "/usr/lib/python3.10/urllib/request.py", line 634, in http_response
    response = self.parent.error(
  File "/usr/lib/python3.10/urllib/request.py", line 563, in error
    return self._call_chain(*args)
  File "/usr/lib/python3.10/urllib/request.py", line 496, in _call_chain
    result = func(*args)
  File "/usr/lib/python3.10/urllib/request.py", line 643, in http_error_default
    raise HTTPError(req.full_url, code, msg, hdrs, fp)
urllib.error.HTTPError: HTTP Error 301: Moved Permenantly

======================================================================
ERROR: test_html (__main__.TestYourWebserver)
----------------------------------------------------------------------
Traceback (most recent call last):
  File "/mnt/d/Program Files (x86)/UNIVERSITY/CMPUT/CMPUT 404/Assignments/Assignment 1/CMPUT404-assignment-webserver/CMPUT404-assignment-webserver/not-free-tests.py", line 99, in test_html
    req = request.urlopen(url, None, 3)
  File "/usr/lib/python3.10/urllib/request.py", line 216, in urlopen
    return opener.open(url, data, timeout)
  File "/usr/lib/python3.10/urllib/request.py", line 525, in open
    response = meth(req, response)
  File "/usr/lib/python3.10/urllib/request.py", line 634, in http_response
    response = self.parent.error(
  File "/usr/lib/python3.10/urllib/request.py", line 563, in error
    return self._call_chain(*args)
  File "/usr/lib/python3.10/urllib/request.py", line 496, in _call_chain
    result = func(*args)
  File "/usr/lib/python3.10/urllib/request.py", line 643, in http_error_default
    raise HTTPError(req.full_url, code, msg, hdrs, fp)
urllib.error.HTTPError: HTTP Error 301: Moved Permenantly

======================================================================
FAIL: test_get_404 (__main__.TestYourWebserver)
----------------------------------------------------------------------
Traceback (most recent call last):
  File "/mnt/d/Program Files (x86)/UNIVERSITY/CMPUT/CMPUT 404/Assignments/Assignment 1/CMPUT404-assignment-webserver/CMPUT404-assignment-webserver/not-free-tests.py", line 48, in test_get_404
    req = request.urlopen(url, None, 3)
  File "/usr/lib/python3.10/urllib/request.py", line 216, in urlopen
    return opener.open(url, data, timeout)
  File "/usr/lib/python3.10/urllib/request.py", line 525, in open
    response = meth(req, response)
  File "/usr/lib/python3.10/urllib/request.py", line 634, in http_response
    response = self.parent.error(
  File "/usr/lib/python3.10/urllib/request.py", line 563, in error
    return self._call_chain(*args)
  File "/usr/lib/python3.10/urllib/request.py", line 496, in _call_chain
    result = func(*args)
  File "/usr/lib/python3.10/urllib/request.py", line 643, in http_error_default
    raise HTTPError(req.full_url, code, msg, hdrs, fp)
urllib.error.HTTPError: HTTP Error 301: Moved Permenantly

During handling of the above exception, another exception occurred:

Traceback (most recent call last):
  File "/mnt/d/Program Files (x86)/UNIVERSITY/CMPUT/CMPUT 404/Assignments/Assignment 1/CMPUT404-assignment-webserver/CMPUT404-assignment-webserver/not-free-tests.py", line 51, in test_get_404
    self.assertTrue( e.getcode()  == 404 , ("404 Not FOUND! %d" % e.getcode()))
AssertionError: False is not true : 404 Not FOUND! 301

======================================================================
FAIL: test_get_group (__main__.TestYourWebserver)
how secure are you?
----------------------------------------------------------------------
Traceback (most recent call last):
  File "/mnt/d/Program Files (x86)/UNIVERSITY/CMPUT/CMPUT 404/Assignments/Assignment 1/CMPUT404-assignment-webserver/CMPUT404-assignment-webserver/not-free-tests.py", line 59, in test_get_group
    req = request.urlopen(url, None, 3)
  File "/usr/lib/python3.10/urllib/request.py", line 216, in urlopen
    return opener.open(url, data, timeout)
  File "/usr/lib/python3.10/urllib/request.py", line 525, in open
    response = meth(req, response)
  File "/usr/lib/python3.10/urllib/request.py", line 634, in http_response
    response = self.parent.error(
  File "/usr/lib/python3.10/urllib/request.py", line 563, in error
    return self._call_chain(*args)
  File "/usr/lib/python3.10/urllib/request.py", line 496, in _call_chain
    result = func(*args)
  File "/usr/lib/python3.10/urllib/request.py", line 643, in http_error_default
    raise HTTPError(req.full_url, code, msg, hdrs, fp)
urllib.error.HTTPError: HTTP Error 301: Moved Permenantly

During handling of the above exception, another exception occurred:

Traceback (most recent call last):
  File "/mnt/d/Program Files (x86)/UNIVERSITY/CMPUT/CMPUT 404/Assignments/Assignment 1/CMPUT404-assignment-webserver/CMPUT404-assignment-webserver/not-free-tests.py", line 62, in test_get_group
    self.assertTrue( e.getcode()  == 404 , ("404 Not FOUND! %d" % e.getcode()))
AssertionError: False is not true : 404 Not FOUND! 301

======================================================================
FAIL: test_hardcode2 (__main__.TestYourWebserver)
----------------------------------------------------------------------
Traceback (most recent call last):
  File "/mnt/d/Program Files (x86)/UNIVERSITY/CMPUT/CMPUT 404/Assignments/Assignment 1/CMPUT404-assignment-webserver/CMPUT404-assignment-webserver/not-free-tests.py", line 117, in test_hardcode2
    req = request.urlopen(url, None, 3)
  File "/usr/lib/python3.10/urllib/request.py", line 216, in urlopen
    return opener.open(url, data, timeout)
  File "/usr/lib/python3.10/urllib/request.py", line 525, in open
    response = meth(req, response)
  File "/usr/lib/python3.10/urllib/request.py", line 634, in http_response
    response = self.parent.error(
  File "/usr/lib/python3.10/urllib/request.py", line 563, in error
    return self._call_chain(*args)
  File "/usr/lib/python3.10/urllib/request.py", line 496, in _call_chain
    result = func(*args)
  File "/usr/lib/python3.10/urllib/request.py", line 643, in http_error_default
    raise HTTPError(req.full_url, code, msg, hdrs, fp)
urllib.error.HTTPError: HTTP Error 301: Moved Permenantly

During handling of the above exception, another exception occurred:

Traceback (most recent call last):
  File "/mnt/d/Program Files (x86)/UNIVERSITY/CMPUT/CMPUT 404/Assignments/Assignment 1/CMPUT404-assignment-webserver/CMPUT404-assignment-webserver/not-free-tests.py", line 120, in test_hardcode2
    self.assertTrue( e.getcode()  == 404 , ("404 Not FOUND! %d" % e.getcode()))
AssertionError: False is not true : 404 Not FOUND! 301

----------------------------------------------------------------------
Ran 11 tests in 0.052s

FAILED (failures=3, errors=4)
